Workbook
Name LU_Modules: OFFSET('Lookup Values'!$G$2,0,0,COUNTA('Lookup Values'!$G$2:$G$1000),1)
Name LU_Statuses: OFFSET('Lookup Values'!$C$2,0,0,COUNTA('Lookup Values'!$C$2:$C$1000),1)
Name LU_StoryPoints: OFFSET('Lookup Values'!$E$2,0,0,COUNTA('Lookup Values'!$E$2:$E$1000),1)
Name LU_Types: OFFSET('Lookup Values'!$A$2,0,0,COUNTA('Lookup Values'!$A$2:$A$1000),1)

Sheet Home Dashboard
A1: WayPoint Project Tracker - Home Dashboard
A3: Project Name | B3: WayPoint
A4: Methodology | B4: Kanban
A5: Ticket Format | B5: WPT-001
A7: Total Tickets | C7: Backlog | E7: Ready | G7: In Progress | I7: Testing
A8: =COUNTA(tblTickets[Ticket ID]) -> 160 | C8: =COUNTIF(tblTickets[Status],"Backlog") -> 150 | E8: =COUNTIF(tblTickets[Status],"Ready") -> 0 | G8: =COUNTIF(tblTickets[Status],"In Progress") -> 5 | I8: =COUNTIF(tblTickets[Status],"Testing") -> 0
A10: Done | C10: Total Story Points | E10: Completed SP | G10: Remaining SP | I10: Completion %
A11: =COUNTIF(tblTickets[Status],"Done") -> 5 | C11: =SUM(tblTickets[Story Points]) -> 722 | E11: =SUMIFS(tblTickets[Story Points],tblTickets[Status],"Done") -> 18 | G11: =SUM(tblTickets[Story Points])-SUMIFS(tblTickets[Story Points],tblTickets[Status],"Done") -> 704 | I11: =IFERROR(SUMIFS(tblTickets[Story Points],tblTickets[Status],"Done")/SUM(tblTickets[Story Points]),0) -> 0.024930748
A15: Select Team Member | B15: TBD | J15: Status | K15: Count
J16: Backlog | K16: =COUNTIF(tblTickets[Status],J16) -> 150
A17: Assigned Tickets | B17: Open Tickets | C17: Completed Tickets | D17: Assigned SP | E17: Completed SP | F17: Remaining SP | G17: Completion % | H17: In Progress | I17: Testing | J17: Ready | K17: =COUNTIF(tblTickets[Status],J17) -> 0
A18: =COUNTIF(tblTickets[Assignee],$B$15) -> 136 | B18: =COUNTIFS(tblTickets[Assignee],$B$15,tblTickets[Status],"<>Done") -> 136 | C18: =COUNTIFS(tblTickets[Assignee],$B$15,tblTickets[Status],"Done") -> 0 | D18: =SUMIF(tblTickets[Assignee],$B$15,tblTickets[Story Points]) -> 620 | E18: =SUMIFS(tblTickets[Story Points],tblTickets[Assignee],$B$15,tblTickets[Status],"Done") -> 0 | F18: =SUMIF(tblTickets[Assignee],$B$15,tblTickets[Story Points])-SUMIFS(tblTickets[Story Points],tblTickets[Assignee],$B$15,tblTickets[Status],"Done") -> 620 | G18: =IFERROR(SUMIFS(tblTickets[Story Points],tblTickets[Assignee],$B$15,tblTickets[Status],"Done")/SUMIF(tblTickets[Assignee],$B$15,tblTickets[Story Points]),0) -> 0 | H18: =COUNTIFS(tblTickets[Assignee],$B$15,tblTickets[Status],"In Progress") -> 0 | I18: =COUNTIFS(tblTickets[Assignee],$B$15,tblTickets[Status],"Testing") -> 0 | J18: In Progress | K18: =COUNTIF(tblTickets[Status],J18) -> 5
J19: Testing | K19: =COUNTIF(tblTickets[Status],J19) -> 0
J20: Done | K20: =COUNTIF(tblTickets[Status],J20) -> 5
A21: Selected Team Member Tickets
A22: Ticket ID | B22: Type | C22: Module | D22: Title | E22: Status | F22: SP
A23: =IFERROR(INDEX(Tickets!$A$2:$A$161,_xlfn.AGGREGATE(15,6,(ROW(Tickets!$F$2:$F$161)-ROW(Tickets!$F$2)+1)/(Tickets!$F$2:$F$161=$B$15),ROWS($A$23:A23))),"") -> WPT-024 | B23: =IFERROR(INDEX(Tickets!$C$2:$C$161,_xlfn.AGGREGATE(15,6,(ROW(Tickets!$F$2:$F$161)-ROW(Tickets!$F$2)+1)/(Tickets!$F$2:$F$161=$B$15),ROWS($A$23:A23))),"") -> Story | C23: =IFERROR(INDEX(Tickets!$D$2:$D$161,_xlfn.AGGREGATE(15,6,(ROW(Tickets!$F$2:$F$161)-ROW(Tickets!$F$2)+1)/(Tickets!$F$2:$F$161=$B$15),ROWS($A$23:A23))),"") -> Authentication | D23: =IFERROR(INDEX(Tickets!$E$2:$E$161,_xlfn.AGGREGATE(15,6,(ROW(Tickets!$F$2:$F$161)-ROW(Tickets!$F$2)+1)/(Tickets!$F$2:$F$161=$B$15),ROWS($A$23:A23))),"") -> Password and logout management | E23: =IFERROR(INDEX(Tickets!$G$2:$G$161,_xlfn.AGGREGATE(15,6,(ROW(Tickets!$F$2:$F$161)-ROW(Tickets!$F$2)+1)/(Tickets!$F$2:$F$161=$B$15),ROWS($A$23:A23))),"") -> Backlog | F23: =IFERROR(INDEX(Tickets!$H$2:$H$161,_xlfn.AGGREGATE(15,6,(ROW(Tickets!$F$2:$F$161)-ROW(Tickets!$F$2)+1)/(Tickets!$F$2:$F$161=$B$15),ROWS($A$23:A23))),"") -> 5
A24: =IFERROR(INDEX(Tickets!$A$2:$A$161,_xlfn.AGGREGATE(15,6,(ROW(Tickets!$F$2:$F$161)-ROW(Tickets!$F$2)+1)/(Tickets!$F$2:$F$161=$B$15),ROWS($A$23:A24))),"") -> WPT-025 | B24: =IFERROR(INDEX(Tickets!$C$2:$C$161,_xlfn.AGGREGATE(15,6,(ROW(Tickets!$F$2:$F$161)-ROW(Tickets!$F$2)+1)/(Tickets!$F$2:$F$161=$B$15),ROWS($A$23:A24))),"") -> Task | C24: =IFERROR(INDEX(Tickets!$D$2:$D$161,_xlfn.AGGREGATE(15,6,(ROW(Tickets!$F$2:$F$161)-ROW(Tickets!$F$2)+1)/(Tickets!$F$2:$F$161=$B$15),ROWS($A$23:A24))),"") -> Authentication | D24: =IFERROR(INDEX(Tickets!$E$2:$E$161,_xlfn.AGGREGATE(15,6,(ROW(Tickets!$F$2:$F$161)-ROW(Tickets!$F$2)+1)/(Tickets!$F$2:$F$161=$B$15),ROWS($A$23:A24))),"") -> Create change password screen | E24: =IFERROR(INDEX(Tickets!$G$2:$G$161,_xlfn.AGGREGATE(15,6,(ROW(Tickets!$F$2:$F$161)-ROW(Tickets!$F$2)+1)/(Tickets!$F$2:$F$161=$B$15),ROWS($A$23:A24))),"") -> Backlog | F24: =IFERROR(INDEX(Tickets!$H$2:$H$161,_xlfn.AGGREGATE(15,6,(ROW(Tickets!$F$2:$F$161)-ROW(Tickets!$F$2)+1)/(Tickets!$F$2:$F$161=$B$15),ROWS($A$23:A24))),"") -> 3
A25: =IFERROR(INDEX(Tickets!$A$2:$A$161,_xlfn.AGGREGATE(15,6,(ROW(Tickets!$F$2:$F$161)-ROW(Tickets!$F$2)+1)/(Tickets!$F$2:$F$161=$B$15),ROWS($A$23:A25))),"") -> WPT-026 | B25: =IFERROR(INDEX(Tickets!$C$2:$C$161,_xlfn.AGGREGATE(15,6,(ROW(Tickets!$F$2:$F$161)-ROW(Tickets!$F$2)+1)/(Tickets!$F$2:$F$161=$B$15),ROWS($A$23:A25))),"") -> Task | C25: =IFERROR(INDEX(Tickets!$D$2:$D$161,_xlfn.AGGREGATE(15,6,(ROW(Tickets!$F$2:$F$161)-ROW(Tickets!$F$2)+1)/(Tickets!$F$2:$F$161=$B$15),ROWS($A$23:A25))),"") -> Authentication | D25: =IFERROR(INDEX(Tickets!$E$2:$E$161,_xlfn.AGGREGATE(15,6,(ROW(Tickets!$F$2:$F$161)-ROW(Tickets!$F$2)+1)/(Tickets!$F$2:$F$161=$B$15),ROWS($A$23:A25))),"") -> Create logout function | E25: =IFERROR(INDEX(Tickets!$G$2:$G$161,_xlfn.AGGREGATE(15,6,(ROW(Tickets!$F$2:$F$161)-ROW(Tickets!$F$2)+1)/(Tickets!$F$2:$F$161=$B$15),ROWS($A$23:A25))),"") -> Backlog | F25: =IFERROR(INDEX(Tickets!$H$2:$H$161,_xlfn.AGGREGATE(15,6,(ROW(Tickets!$F$2:$F$161)-ROW(Tickets!$F$2)+1)/(Tickets!$F$2:$F$161=$B$15),ROWS($A$23:A25))),"") -> 2
A26: =IFERROR(INDEX(Tickets!$A$2:$A$161,_xlfn.AGGREGATE(15,6,(ROW(Tickets!$F$2:$F$161)-ROW(Tickets!$F$2)+1)/(Tickets!$F$2:$F$161=$B$15),ROWS($A$23:A26))),"") -> WPT-027 | B26: =IFERROR(INDEX(Tickets!$C$2:$C$161,_xlfn.AGGREGATE(15,6,(ROW(Tickets!$F$2:$F$161)-ROW(Tickets!$F$2)+1)/(Tickets!$F$2:$F$161=$B$15),ROWS($A$23:A26))),"") -> Epic | C26: =IFERROR(INDEX(Tickets!$D$2:$D$161,_xlfn.AGGREGATE(15,6,(ROW(Tickets!$F$2:$F$161)-ROW(Tickets!$F$2)+1)/(Tickets!$F$2:$F$161=$B$15),ROWS($A$23:A26))),"") -> Employer Portal | D26: =IFERROR(INDEX(Tickets!$E$2:$E$161,_xlfn.AGGREGATE(15,6,(ROW(Tickets!$F$2:$F$161)-ROW(Tickets!$F$2)+1)/(Tickets!$F$2:$F$161=$B$15),ROWS($A$23:A26))),"") -> Employer Dashboard and Profile | E26: =IFERROR(INDEX(Tickets!$G$2:$G$161,_xlfn.AGGREGATE(15,6,(ROW(Tickets!$F$2:$F$161)-ROW(Tickets!$F$2)+1)/(Tickets!$F$2:$F$161=$B$15),ROWS($A$23:A26))),"") -> Backlog | F26: =IFERROR(INDEX(Tickets!$H$2:$H$161,_xlfn.AGGREGATE(15,6,(ROW(Tickets!$F$2:$F$161)-ROW(Tickets!$F$2)+1)/(Tickets!$F$2:$F$161=$B$15),ROWS($A$23:A26))),"") -> 0
A27: =IFERROR(INDEX(Tickets!$A$2:$A$161,_xlfn.AGGREGATE(15,6,(ROW(Tickets!$F$2:$F$161)-ROW(Tickets!$F$2)+1)/(Tickets!$F$2:$F$161=$B$15),ROWS($A$23:A27))),"") -> WPT-028 | B27: =IFERROR(INDEX(Tickets!$C$2:$C$161,_xlfn.AGGREGATE(15,6,(ROW(Tickets!$F$2:$F$161)-ROW(Tickets!$F$2)+1)/(Tickets!$F$2:$F$161=$B$15),ROWS($A$23:A27))),"") -> Story | C27: =IFERROR(INDEX(Tickets!$D$2:$D$161,_xlfn.AGGREGATE(15,6,(ROW(Tickets!$F$2:$F$161)-ROW(Tickets!$F$2)+1)/(Tickets!$F$2:$F$161=$B$15),ROWS($A$23:A27))),"") -> Employer Profile | D27: =IFERROR(INDEX(Tickets!$E$2:$E$161,_xlfn.AGGREGATE(15,6,(ROW(Tickets!$F$2:$F$161)-ROW(Tickets!$F$2)+1)/(Tickets!$F$2:$F$161=$B$15),ROWS($A$23:A27))),"") -> Employer profile management | E27: =IFERROR(INDEX(Tickets!$G$2:$G$161,_xlfn.AGGREGATE(15,6,(ROW(Tickets!$F$2:$F$161)-ROW(Tickets!$F$2)+1)/(Tickets!$F$2:$F$161=$B$15),ROWS($A$23:A27))),"") -> Backlog | F27: =IFERROR(INDEX(Tickets!$H$2:$H$161,_xlfn.AGGREGATE(15,6,(ROW(Tickets!$F$2:$F$161)-ROW(Tickets!$F$2)+1)/(Tickets!$F$2:$F$161=$B$15),ROWS($A$23:A27))),"") -> 8
A28: =IFERROR(INDEX(Tickets!$A$2:$A$161,_xlfn.AGGREGATE(15,6,(ROW(Tickets!$F$2:$F$161)-ROW(Tickets!$F$2)+1)/(Tickets!$F$2:$F$161=$B$15),ROWS($A$23:A28))),"") -> WPT-029 | B28: =IFERROR(INDEX(Tickets!$C$2:$C$161,_xlfn.AGGREGATE(15,6,(ROW(Tickets!$F$2:$F$161)-ROW(Tickets!$F$2)+1)/(Tickets!$F$2:$F$161=$B$15),ROWS($A$23:A28))),"") -> Task | C28: =IFERROR(INDEX(Tickets!$D$2:$D$161,_xlfn.AGGREGATE(15,6,(ROW(Tickets!$F$2:$F$161)-ROW(Tickets!$F$2)+1)/(Tickets!$F$2:$F$161=$B$15),ROWS($A$23:A28))),"") -> Employer Profile | D28: =IFERROR(INDEX(Tickets!$E$2:$E$161,_xlfn.AGGREGATE(15,6,(ROW(Tickets!$F$2:$F$161)-ROW(Tickets!$F$2)+1)/(Tickets!$F$2:$F$161=$B$15),ROWS($A$23:A28))),"") -> Create employer profile page | E28: =IFERROR(INDEX(Tickets!$G$2:$G$161,_xlfn.AGGREGATE(15,6,(ROW(Tickets!$F$2:$F$161)-ROW(Tickets!$F$2)+1)/(Tickets!$F$2:$F$161=$B$15),ROWS($A$23:A28))),"") -> Backlog | F28: =IFERROR(INDEX(Tickets!$H$2:$H$161,_xlfn.AGGREGATE(15,6,(ROW(Tickets!$F$2:$F$161)-ROW(Tickets!$F$2)+1)/(Tickets!$F$2:$F$161=$B$15),ROWS($A$23:A28))),"") -> 5
A29: =IFERROR(INDEX(Tickets!$A$2:$A$161,_xlfn.AGGREGATE(15,6,(ROW(Tickets!$F$2:$F$161)-ROW(Tickets!$F$2)+1)/(Tickets!$F$2:$F$161=$B$15),ROWS($A$23:A29))),"") -> WPT-030 | B29: =IFERROR(INDEX(Tickets!$C$2:$C$161,_xlfn.AGGREGATE(15,6,(ROW(Tickets!$F$2:$F$161)-ROW(Tickets!$F$2)+1)/(Tickets!$F$2:$F$161=$B$15),ROWS($A$23:A29))),"") -> Task | C29: =IFERROR(INDEX(Tickets!$D$2:$D$161,_xlfn.AGGREGATE(15,6,(ROW(Tickets!$F$2:$F$161)-ROW(Tickets!$F$2)+1)/(Tickets!$F$2:$F$161=$B$15),ROWS($A$23:A29))),"") -> Employer Profile | D29: =IFERROR(INDEX(Tickets!$E$2:$E$161,_xlfn.AGGREGATE(15,6,(ROW(Tickets!$F$2:$F$161)-ROW(Tickets!$F$2)+1)/(Tickets!$F$2:$F$161=$B$15),ROWS($A$23:A29))),"") -> Create edit company profile function | E29: =IFERROR(INDEX(Tickets!$G$2:$G$161,_xlfn.AGGREGATE(15,6,(ROW(Tickets!$F$2:$F$161)-ROW(Tickets!$F$2)+1)/(Tickets!$F$2:$F$161=$B$15),ROWS($A$23:A29))),"") -> Backlog | F29: =IFERROR(INDEX(Tickets!$H$2:$H$161,_xlfn.AGGREGATE(15,6,(ROW(Tickets!$F$2:$F$161)-ROW(Tickets!$F$2)+1)/(Tickets!$F$2:$F$161=$B$15),ROWS($A$23:A29))),"") -> 5
A30: =IFERROR(INDEX(Tickets!$A$2:$A$161,_xlfn.AGGREGATE(15,6,(ROW(Tickets!$F$2:$F$161)-ROW(Tickets!$F$2)+1)/(Tickets!$F$2:$F$161=$B$15),ROWS($A$23:A30))),"") -> WPT-031 | B30: =IFERROR(INDEX(Tickets!$C$2:$C$161,_xlfn.AGGREGATE(15,6,(ROW(Tickets!$F$2:$F$161)-ROW(Tickets!$F$2)+1)/(Tickets!$F$2:$F$161=$B$15),ROWS($A$23:A30))),"") -> Task | C30: =IFERROR(INDEX(Tickets!$D$2:$D$161,_xlfn.AGGREGATE(15,6,(ROW(Tickets!$F$2:$F$161)-ROW(Tickets!$F$2)+1)/(Tickets!$F$2:$F$161=$B$15),ROWS($A$23:A30))),"") -> Employer Profile | D30: =IFERROR(INDEX(Tickets!$E$2:$E$161,_xlfn.AGGREGATE(15,6,(ROW(Tickets!$F$2:$F$161)-ROW(Tickets!$F$2)+1)/(Tickets!$F$2:$F$161=$B$15),ROWS($A$23:A30))),"") -> Create employer profile API | E30: =IFERROR(INDEX(Tickets!$G$2:$G$161,_xlfn.AGGREGATE(15,6,(ROW(Tickets!$F$2:$F$161)-ROW(Tickets!$F$2)+1)/(Tickets!$F$2:$F$161=$B$15),ROWS($A$23:A30))),"") -> Backlog | F30: =IFERROR(INDEX(Tickets!$H$2:$H$161,_xlfn.AGGREGATE(15,6,(ROW(Tickets!$F$2:$F$161)-ROW(Tickets!$F$2)+1)/(Tickets!$F$2:$F$161=$B$15),ROWS($A$23:A30))),"") -> 5
A31: =IFERROR(INDEX(Tickets!$A$2:$A$161,_xlfn.AGGREGATE(15,6,(ROW(Tickets!$F$2:$F$161)-ROW(Tickets!$F$2)+1)/(Tickets!$F$2:$F$161=$B$15),ROWS($A$23:A31))),"") -> WPT-032 | B31: =IFERROR(INDEX(Tickets!$C$2:$C$161,_xlfn.AGGREGATE(15,6,(ROW(Tickets!$F$2:$F$161)-ROW(Tickets!$F$2)+1)/(Tickets!$F$2:$F$161=$B$15),ROWS($A$23:A31))),"") -> Story | C31: =IFERROR(INDEX(Tickets!$D$2:$D$161,_xlfn.AGGREGATE(15,6,(ROW(Tickets!$F$2:$F$161)-ROW(Tickets!$F$2)+1)/(Tickets!$F$2:$F$161=$B$15),ROWS($A$23:A31))),"") -> Employer Dashboard | D31: =IFERROR(INDEX(Tickets!$E$2:$E$161,_xlfn.AGGREGATE(15,6,(ROW(Tickets!$F$2:$F$161)-ROW(Tickets!$F$2)+1)/(Tickets!$F$2:$F$161=$B$15),ROWS($A$23:A31))),"") -> Employer home dashboard | E31: =IFERROR(INDEX(Tickets!$G$2:$G$161,_xlfn.AGGREGATE(15,6,(ROW(Tickets!$F$2:$F$161)-ROW(Tickets!$F$2)+1)/(Tickets!$F$2:$F$161=$B$15),ROWS($A$23:A31))),"") -> Backlog | F31: =IFERROR(INDEX(Tickets!$H$2:$H$161,_xlfn.AGGREGATE(15,6,(ROW(Tickets!$F$2:$F$161)-ROW(Tickets!$F$2)+1)/(Tickets!$F$2:$F$161=$B$15),ROWS($A$23:A31))),"") -> 8
A32: =IFERROR(INDEX(Tickets!$A$2:$A$161,_xlfn.AGGREGATE(15,6,(ROW(Tickets!$F$2:$F$161)-ROW(Tickets!$F$2)+1)/(Tickets!$F$2:$F$161=$B$15),ROWS($A$23:A32))),"") -> WPT-033 | B32: =IFERROR(INDEX(Tickets!$C$2:$C$161,_xlfn.AGGREGATE(15,6,(ROW(Tickets!$F$2:$F$161)-ROW(Tickets!$F$2)+1)/(Tickets!$F$2:$F$161=$B$15),ROWS($A$23:A32))),"") -> Task | C32: =IFERROR(INDEX(Tickets!$D$2:$D$161,_xlfn.AGGREGATE(15,6,(ROW(Tickets!$F$2:$F$161)-ROW(Tickets!$F$2)+1)/(Tickets!$F$2:$F$161=$B$15),ROWS($A$23:A32))),"") -> Employer Dashboard | D32: =IFERROR(INDEX(Tickets!$E$2:$E$161,_xlfn.AGGREGATE(15,6,(ROW(Tickets!$F$2:$F$161)-ROW(Tickets!$F$2)+1)/(Tickets!$F$2:$F$161=$B$15),ROWS($A$23:A32))),"") -> Show total jobs posted | E32: =IFERROR(INDEX(Tickets!$G$2:$G$161,_xlfn.AGGREGATE(15,6,(ROW(Tickets!$F$2:$F$161)-ROW(Tickets!$F$2)+1)/(Tickets!$F$2:$F$161=$B$15),ROWS($A$23:A32))),"") -> Backlog | F32: =IFERROR(INDEX(Tickets!$H$2:$H$161,_xlfn.AGGREGATE(15,6,(ROW(Tickets!$F$2:$F$161)-ROW(Tickets!$F$2)+1)/(Tickets!$F$2:$F$161=$B$15),ROWS($A$23:A32))),"") -> 3
A33: =IFERROR(INDEX(Tickets!$A$2:$A$161,_xlfn.AGGREGATE(15,6,(ROW(Tickets!$F$2:$F$161)-ROW(Tickets!$F$2)+1)/(Tickets!$F$2:$F$161=$B$15),ROWS($A$23:A33))),"") -> WPT-034 | B33: =IFERROR(INDEX(Tickets!$C$2:$C$161,_xlfn.AGGREGATE(15,6,(ROW(Tickets!$F$2:$F$161)-ROW(Tickets!$F$2)+1)/(Tickets!$F$2:$F$161=$B$15),ROWS($A$23:A33))),"") -> Task | C33: =IFERROR(INDEX(Tickets!$D$2:$D$161,_xlfn.AGGREGATE(15,6,(ROW(Tickets!$F$2:$F$161)-ROW(Tickets!$F$2)+1)/(Tickets!$F$2:$F$161=$B$15),ROWS($A$23:A33))),"") -> Employer Dashboard | D33: =IFERROR(INDEX(Tickets!$E$2:$E$161,_xlfn.AGGREGATE(15,6,(ROW(Tickets!$F$2:$F$161)-ROW(Tickets!$F$2)+1)/(Tickets!$F$2:$F$161=$B$15),ROWS($A$23:A33))),"") -> Show new applications count | E33: =IFERROR(INDEX(Tickets!$G$2:$G$161,_xlfn.AGGREGATE(15,6,(ROW(Tickets!$F$2:$F$161)-ROW(Tickets!$F$2)+1)/(Tickets!$F$2:$F$161=$B$15),ROWS($A$23:A33))),"") -> Backlog | F33: =IFERROR(INDEX(Tickets!$H$2:$H$161,_xlfn.AGGREGATE(15,6,(ROW(Tickets!$F$2:$F$161)-ROW(Tickets!$F$2)+1)/(Tickets!$F$2:$F$161=$B$15),ROWS($A$23:A33))),"") -> 3
A34: =IFERROR(INDEX(Tickets!$A$2:$A$161,_xlfn.AGGREGATE(15,6,(ROW(Tickets!$F$2:$F$161)-ROW(Tickets!$F$2)+1)/(Tickets!$F$2:$F$161=$B$15),ROWS($A$23:A34))),"") -> WPT-035 | B34: =IFERROR(INDEX(Tickets!$C$2:$C$161,_xlfn.AGGREGATE(15,6,(ROW(Tickets!$F$2:$F$161)-ROW(Tickets!$F$2)+1)/(Tickets!$F$2:$F$161=$B$15),ROWS($A$23:A34))),"") -> Task | C34: =IFERROR(INDEX(Tickets!$D$2:$D$161,_xlfn.AGGREGATE(15,6,(ROW(Tickets!$F$2:$F$161)-ROW(Tickets!$F$2)+1)/(Tickets!$F$2:$F$161=$B$15),ROWS($A$23:A34))),"") -> Employer Dashboard | D34: =IFERROR(INDEX(Tickets!$E$2:$E$161,_xlfn.AGGREGATE(15,6,(ROW(Tickets!$F$2:$F$161)-ROW(Tickets!$F$2)+1)/(Tickets!$F$2:$F$161=$B$15),ROWS($A$23:A34))),"") -> Show in progress Employees count | E34: =IFERROR(INDEX(Tickets!$G$2:$G$161,_xlfn.AGGREGATE(15,6,(ROW(Tickets!$F$2:$F$161)-ROW(Tickets!$F$2)+1)/(Tickets!$F$2:$F$161=$B$15),ROWS($A$23:A34))),"") -> Backlog | F34: =IFERROR(INDEX(Tickets!$H$2:$H$161,_xlfn.AGGREGATE(15,6,(ROW(Tickets!$F$2:$F$161)-ROW(Tickets!$F$2)+1)/(Tickets!$F$2:$F$161=$B$15),ROWS($A$23:A34))),"") -> 3
... A72: =IFERROR(INDEX(Tickets!$A$2:$A$161,_xlfn.AGGREGATE(15,6,(ROW(Tickets!$F$2:$F$161)-ROW(Tickets!$F$2)+1)/(Tickets!$F$2:$F$161=$B$15),ROWS($A$23:A72))),"") -> WPT-073 | B72: =IFERROR(INDEX(Tickets!$C$2:$C$161,_xlfn.AGGREGATE(15,6,(ROW(Tickets!$F$2:$F$161)-ROW(Tickets!$F$2)+1)/(Tickets!$F$2:$F$161=$B$15),ROWS($A$23:A72))),"") -> Task | C72: =IFERROR(INDEX(Tickets!$D$2:$D$161,_xlfn.AGGREGATE(15,6,(ROW(Tickets!$F$2:$F$161)-ROW(Tickets!$F$2)+1)/(Tickets!$F$2:$F$161=$B$15),ROWS($A$23:A72))),"") -> Employer Event Management | D72: =IFERROR(INDEX(Tickets!$E$2:$E$161,_xlfn.AGGREGATE(15,6,(ROW(Tickets!$F$2:$F$161)-ROW(Tickets!$F$2)+1)/(Tickets!$F$2:$F$161=$B$15),ROWS($A$23:A72))),"") -> Display event information | E72: =IFERROR(INDEX(Tickets!$G$2:$G$161,_xlfn.AGGREGATE(15,6,(ROW(Tickets!$F$2:$F$161)-ROW(Tickets!$F$2)+1)/(Tickets!$F$2:$F$161=$B$15),ROWS($A$23:A72))),"") -> Backlog | F72: =IFERROR(INDEX(Tickets!$H$2:$H$161,_xlfn.AGGREGATE(15,6,(ROW(Tickets!$F$2:$F$161)-ROW(Tickets!$F$2)+1)/(Tickets!$F$2:$F$161=$B$15),ROWS($A$23:A72))),"") -> 3

Sheet Tickets
A1: Ticket ID | B1: Parent ID | C1: Type | D1: Module | E1: Title | F1: Assignee | G1: Status | H1: Story Points | I1: Created Date | J1: Start Date | K1: Target Date | L1: Completed Date | M1: Notes
A2: WPT-001 | C2: Epic | D2: Project Foundation | E2: WayPoint Application Foundation | F2: Pragna | G2: Done | H2: 0 | M2: Core application setup
A3: WPT-002 | B3: WPT-001 | C3: Story | D3: Project Foundation | E3: Set up React full stack project structure | F3: Pragna | G3: Done | H3: 5 | M3: Create frontend and backend base structure
A4: WPT-003 | B4: WPT-002 | C4: Task | D4: Project Foundation | E4: Create frontend React application | F4: Pragna | G4: Done | H4: 3 | M4: Set up app shell and routing
A5: WPT-004 | B5: WPT-002 | C5: Task | D5: Project Foundation | E5: Create backend API project | F5: Pragna | G5: Done | H5: 5 | M5: Set up backend services
A6: WPT-005 | B6: WPT-002 | C6: Task | D6: Project Foundation | E6: Set up database connection | F6: Pragna | G6: Done | H6: 5 | M6: Connect backend to database
A7: WPT-006 | B7: WPT-002 | C7: Subtask | D7: Project Foundation | E7: Create environment configuration | F7: Pragna | G7: In Progress | H7: 2 | M7: Add dev/test/prod config placeholders
A8: WPT-007 | B8: WPT-001 | C8: Story | D8: Project Foundation | E8: Create shared navigation layout | F8: Pragna | G8: In Progress | H8: 5 | M8: Common navbar for employer and Employee
A9: WPT-008 | B9: WPT-007 | C9: Task | D9: Shared UI | E9: Create top navigation bar | F9: Pragna | G9: In Progress | H9: 3 | M9: Navbar with dashboard links
A10: WPT-009 | B10: WPT-007 | C10: Task | D10: Shared UI | E10: Create profile icon menu | F10: Pragna | G10: In Progress | H10: 3 | M10: Profile
A11: WPT-010 | B11: WPT-007 | C11: Task | D11: Shared UI | E11: Create reusable dashboard card component | F11: Pragna | G11: In Progress | H11: 3 | M11: Used for counts and summary metrics
A12: WPT-011 | C12: Epic | D12: Authentication | E12: Registration and Login | F12: Pragna | G12: Backlog | H12: 0 | M12: Employer and Employee authentication
A13: WPT-012 | B13: WPT-011 | C13: Story | D13: Authentication | E13: Employer registration | F13: Pragna | G13: Backlog | H13: 8 | M13: Employer can create account
A14: WPT-013 | B14: WPT-012 | C14: Task | D14: Authentication | E14: Create employer registration UI | F14: Pragna | G14: Backlog | H14: 5 | M14: Registration form
A15: WPT-014 | B15: WPT-012 | C15: Task | D15: Authentication | E15: Create employer registration API | F15: Pragna | G15: Backlog | H15: 5 | M15: Save employer account
A16: WPT-015 | B16: WPT-012 | C16: Task | D16: Authentication | E16: Validate employer registration fields | F16: Pragna | G16: Backlog | H16: 3 | M16: Required fields and email validation
A17: WPT-016 | B17: WPT-011 | C17: Story | D17: Authentication | E17: Employee registration | F17: Jhansi | G17: Backlog | H17: 8 | M17: Employee can create account
A18: WPT-017 | B18: WPT-016 | C18: Task | D18: Authentication | E18: Create Employee registration UI | F18: Jhansi | G18: Backlog | H18: 5 | M18: Registration form
A19: WPT-018 | B19: WPT-016 | C19: Task | D19: Authentication | E19: Create Employee registration API | F19: Jhansi | G19: Backlog | H19: 5 | M19: Save Employee account
A20: WPT-019 | B20: WPT-016 | C20: Task | D20: Authentication | E20: Validate Employee registration fields | F20: Jhansi | G20: Backlog | H20: 3 | M20: Required fields and email validation
A21: WPT-020 | B21: WPT-011 | C21: Story | D21: Authentication | E21: Login for employer and Employee | F21: Pragna | G21: Backlog | H21: 8 | M21: Role based login
A22: WPT-021 | B22: WPT-020 | C22: Task | D22: Authentication | E22: Create login UI | F22: Pragna | G22: Backlog | H22: 3 | M22: Common login screen
A23: WPT-022 | B23: WPT-020 | C23: Task | D23: Authentication | E23: Create login API | F23: Pragna | G23: Backlog | H23: 5 | M23: Authenticate user
A24: WPT-023 | B24: WPT-020 | C24: Task | D24: Authentication | E24: Redirect user based on account type | F24: Jhansi | G24: Backlog | H24: 5 | M24: Employer to employer dashboard Employee to Employee dashboard
... A27: WPT-026 | B27: WPT-024 | C27: Task | D27: Authentication | E27: Create logout function | F27: TBD | G27: Backlog | H27: 2 | M27: End user session
A28: WPT-027 | C28: Epic | D28: Employer Portal | E28: Employer Dashboard and Profile | F28: TBD | G28: Backlog | H28: 0 | M28: Employer side main experience
A29: WPT-028 | B29: WPT-027 | C29: Story | D29: Employer Profile | E29: Employer profile management | F29: TBD | G29: Backlog | H29: 8 | M29: Employer can edit company information
A30: WPT-029 | B30: WPT-028 | C30: Task | D30: Employer Profile | E30: Create employer profile page | F30: TBD | G30: Backlog | H30: 5 | M30: Company profile details
A31: WPT-030 | B31: WPT-028 | C31: Task | D31: Employer Profile | E31: Create edit company profile function | F31: TBD | G31: Backlog | H31: 5 | M31: Update company name and details
A32: WPT-031 | B32: WPT-028 | C32: Task | D32: Employer Profile | E32: Create employer profile API | F32: TBD | G32: Backlog | H32: 5 | M32: Save and fetch employer profile
A33: WPT-032 | B33: WPT-027 | C33: Story | D33: Employer Dashboard | E33: Employer home dashboard | F33: TBD | G33: Backlog | H33: 8 | M33: Summary dashboard after login
A34: WPT-033 | B34: WPT-032 | C34: Task | D34: Employer Dashboard | E34: Show total jobs posted | F34: TBD | G34: Backlog | H34: 3 | M34: Dashboard card
A35: WPT-034 | B35: WPT-032 | C35: Task | D35: Employer Dashboard | E35: Show new applications count | F35: TBD | G35: Backlog | H35: 3 | M35: Dashboard card
A36: WPT-035 | B36: WPT-032 | C36: Task | D36: Employer Dashboard | E36: Show in progress Employees count | F36: TBD | G36: Backlog | H36: 3 | M36: Dashboard card
A37: WPT-036 | B37: WPT-032 | C37: Task | D37: Employer Dashboard | E37: Show hired Employees count | F37: TBD | G37: Backlog | H37: 3 | M37: Dashboard card
A38: WPT-037 | B38: WPT-032 | C38: Task | D38: Employer Dashboard | E38: Show event summary cards | F38: TBD | G38: Backlog | H38: 3 | M38: Upcoming and completed events
A39: WPT-038 | C39: Epic | D39: Employer Job Management | E39: Employer Job Dashboard and Job Postings | F39: TBD | G39: Backlog | H39: 0 | M39: Employer can manage jobs
A40: WPT-039 | B40: WPT-038 | C40: Story | D40: Employer Job Management | E40: View all job postings | F40: TBD | G40: Backlog | H40: 8 | M40: Employer can see job list
A41: WPT-040 | B41: WPT-039 | C41: Task | D41: Employer Job Management | E41: Create job postings list page | F41: TBD | G41: Backlog | H41: 5 | M41: List view of jobs
A42: WPT-041 | B42: WPT-039 | C42: Task | D42: Employer Job Management | E42: Display job ID and job name | F42: TBD | G42: Backlog | H42: 3 | M42: Columns in job list
...

Sheet Team Members
A1: Name | B1: Role | C1: Primary Skill | D1: Active | E1: Notes
A2: Pragna | B2: TBD | C2: TBD | D2: Yes | E2: Update role/skill later
A3: Vasavi | B3: TBD | C3: TBD | D3: Yes | E3: Update role/skill later
A4: Niharika | B4: TBD | C4: TBD | D4: Yes | E4: Update role/skill later
A5: Arun | B5: TBD | C5: TBD | D5: Yes | E5: Update role/skill later
A6: Giridhar | B6: TBD | C6: TBD | D6: Yes | E6: Update role/skill later
A7: Mahesh | B7: TBD | C7: TBD | D7: Yes | E7: Update role/skill later
A8: Jhansi | B8: TBD | C8: TBD | D8: Yes | E8: Update role/skill later
A9: Geethanjali | B9: TBD | C9: TBD | D9: Yes | E9: Update role/skill later
A10: Mani | B10: TBD | C10: TBD | D10: Yes | E10: Update role/skill later
A11: TBD | B11: Unassigned | C11: TBD | D11: No | E11: Default unassigned placeholder

Sheet Kanban Board
A1: WayPoint Kanban Board
A3: Backlog | C3: Ready | E3: In Progress | G3: Testing | I3: Done
A4: =IFERROR(INDEX(Tickets!$A$2:$A$161,_xlfn.AGGREGATE(15,6,(ROW(Tickets!$G$2:$G$161)-ROW(Tickets!$G$2)+1)/(Tickets!$G$2:$G$161=$A$3),ROWS($A$4:A4)))&" - "&INDEX(Tickets!$E$2:$E$161,_xlfn.AGGREGATE(15,6,(ROW(Tickets!$G$2:$G$161)-ROW(Tickets!$G$2)+1)/(Tickets!$G$2:$G$161=$A$3),ROWS($A$4:A4))),"") -> WPT-011 - Registration and Login | C4: =IFERROR(INDEX(Tickets!$A$2:$A$161,_xlfn.AGGREGATE(15,6,(ROW(Tickets!$G$2:$G$161)-ROW(Tickets!$G$2)+1)/(Tickets!$G$2:$G$161=$C$3),ROWS($C$4:C4)))&" - "&INDEX(Tickets!$E$2:$E$161,_xlfn.AGGREGATE(15,6,(ROW(Tickets!$G$2:$G$161)-ROW(Tickets!$G$2)+1)/(Tickets!$G$2:$G$161=$C$3),ROWS($C$4:C4))),"") | E4: =IFERROR(INDEX(Tickets!$A$2:$A$161,_xlfn.AGGREGATE(15,6,(ROW(Tickets!$G$2:$G$161)-ROW(Tickets!$G$2)+1)/(Tickets!$G$2:$G$161=$E$3),ROWS($E$4:E4)))&" - "&INDEX(Tickets!$E$2:$E$161,_xlfn.AGGREGATE(15,6,(ROW(Tickets!$G$2:$G$161)-ROW(Tickets!$G$2)+1)/(Tickets!$G$2:$G$161=$E$3),ROWS($E$4:E4))),"") -> WPT-006 - Create environment configuration | G4: =IFERROR(INDEX(Tickets!$A$2:$A$161,_xlfn.AGGREGATE(15,6,(ROW(Tickets!$G$2:$G$161)-ROW(Tickets!$G$2)+1)/(Tickets!$G$2:$G$161=$G$3),ROWS($G$4:G4)))&" - "&INDEX(Tickets!$E$2:$E$161,_xlfn.AGGREGATE(15,6,(ROW(Tickets!$G$2:$G$161)-ROW(Tickets!$G$2)+1)/(Tickets!$G$2:$G$161=$G$3),ROWS($G$4:G4))),"") | I4: =IFERROR(INDEX(Tickets!$A$2:$A$161,_xlfn.AGGREGATE(15,6,(ROW(Tickets!$G$2:$G$161)-ROW(Tickets!$G$2)+1)/(Tickets!$G$2:$G$161=$I$3),ROWS($I$4:I4)))&" - "&INDEX(Tickets!$E$2:$E$161,_xlfn.AGGREGATE(15,6,(ROW(Tickets!$G$2:$G$161)-ROW(Tickets!$G$2)+1)/(Tickets!$G$2:$G$161=$I$3),ROWS($I$4:I4))),"") -> WPT-001 - WayPoint Application Foundation
A5: =IFERROR(INDEX(Tickets!$A$2:$A$161,_xlfn.AGGREGATE(15,6,(ROW(Tickets!$G$2:$G$161)-ROW(Tickets!$G$2)+1)/(Tickets!$G$2:$G$161=$A$3),ROWS($A$4:A5)))&" - "&INDEX(Tickets!$E$2:$E$161,_xlfn.AGGREGATE(15,6,(ROW(Tickets!$G$2:$G$161)-ROW(Tickets!$G$2)+1)/(Tickets!$G$2:$G$161=$A$3),ROWS($A$4:A5))),"") -> WPT-012 - Employer registration | C5: =IFERROR(INDEX(Tickets!$A$2:$A$161,_xlfn.AGGREGATE(15,6,(ROW(Tickets!$G$2:$G$161)-ROW(Tickets!$G$2)+1)/(Tickets!$G$2:$G$161=$C$3),ROWS($C$4:C5)))&" - "&INDEX(Tickets!$E$2:$E$161,_xlfn.AGGREGATE(15,6,(ROW(Tickets!$G$2:$G$161)-ROW(Tickets!$G$2)+1)/(Tickets!$G$2:$G$161=$C$3),ROWS($C$4:C5))),"") | E5: =IFERROR(INDEX(Tickets!$A$2:$A$161,_xlfn.AGGREGATE(15,6,(ROW(Tickets!$G$2:$G$161)-ROW(Tickets!$G$2)+1)/(Tickets!$G$2:$G$161=$E$3),ROWS($E$4:E5)))&" - "&INDEX(Tickets!$E$2:$E$161,_xlfn.AGGREGATE(15,6,(ROW(Tickets!$G$2:$G$161)-ROW(Tickets!$G$2)+1)/(Tickets!$G$2:$G$161=$E$3),ROWS($E$4:E5))),"") -> WPT-007 - Create shared navigation layout | G5: =IFERROR(INDEX(Tickets!$A$2:$A$161,_xlfn.AGGREGATE(15,6,(ROW(Tickets!$G$2:$G$161)-ROW(Tickets!$G$2)+1)/(Tickets!$G$2:$G$161=$G$3),ROWS($G$4:G5)))&" - "&INDEX(Tickets!$E$2:$E$161,_xlfn.AGGREGATE(15,6,(ROW(Tickets!$G$2:$G$161)-ROW(Tickets!$G$2)+1)/(Tickets!$G$2:$G$161=$G$3),ROWS($G$4:G5))),"") | I5: =IFERROR(INDEX(Tickets!$A$2:$A$161,_xlfn.AGGREGATE(15,6,(ROW(Tickets!$G$2:$G$161)-ROW(Tickets!$G$2)+1)/(Tickets!$G$2:$G$161=$I$3),ROWS($I$4:I5)))&" - "&INDEX(Tickets!$E$2:$E$161,_xlfn.AGGREGATE(15,6,(ROW(Tickets!$G$2:$G$161)-ROW(Tickets!$G$2)+1)/(Tickets!$G$2:$G$161=$I$3),ROWS($I$4:I5))),"") -> WPT-002 - Set up React full stack project structure
A6: =IFERROR(INDEX(Tickets!$A$2:$A$161,_xlfn.AGGREGATE(15,6,(ROW(Tickets!$G$2:$G$161)-ROW(Tickets!$G$2)+1)/(Tickets!$G$2:$G$161=$A$3),ROWS($A$4:A6)))&" - "&INDEX(Tickets!$E$2:$E$161,_xlfn.AGGREGATE(15,6,(ROW(Tickets!$G$2:$G$161)-ROW(Tickets!$G$2)+1)/(Tickets!$G$2:$G$161=$A$3),ROWS($A$4:A6))),"") -> WPT-013 - Create employer registration UI | C6: =IFERROR(INDEX(Tickets!$A$2:$A$161,_xlfn.AGGREGATE(15,6,(ROW(Tickets!$G$2:$G$161)-ROW(Tickets!$G$2)+1)/(Tickets!$G$2:$G$161=$C$3),ROWS($C$4:C6)))&" - "&INDEX(Tickets!$E$2:$E$161,_xlfn.AGGREGATE(15,6,(ROW(Tickets!$G$2:$G$161)-ROW(Tickets!$G$2)+1)/(Tickets!$G$2:$G$161=$C$3),ROWS($C$4:C6))),"") | E6: =IFERROR(INDEX(Tickets!$A$2:$A$161,_xlfn.AGGREGATE(15,6,(ROW(Tickets!$G$2:$G$161)-ROW(Tickets!$G$2)+1)/(Tickets!$G$2:$G$161=$E$3),ROWS($E$4:E6)))&" - "&INDEX(Tickets!$E$2:$E$161,_xlfn.AGGREGATE(15,6,(ROW(Tickets!$G$2:$G$161)-ROW(Tickets!$G$2)+1)/(Tickets!$G$2:$G$161=$E$3),ROWS($E$4:E6))),"") -> WPT-008 - Create top navigation bar | G6: =IFERROR(INDEX(Tickets!$A$2:$A$161,_xlfn.AGGREGATE(15,6,(ROW(Tickets!$G$2:$G$161)-ROW(Tickets!$G$2)+1)/(Tickets!$G$2:$G$161=$G$3),ROWS($G$4:G6)))&" - "&INDEX(Tickets!$E$2:$E$161,_xlfn.AGGREGATE(15,6,(ROW(Tickets!$G$2:$G$161)-ROW(Tickets!$G$2)+1)/(Tickets!$G$2:$G$161=$G$3),ROWS($G$4:G6))),"") | I6: =IFERROR(INDEX(Tickets!$A$2:$A$161,_xlfn.AGGREGATE(15,6,(ROW(Tickets!$G$2:$G$161)-ROW(Tickets!$G$2)+1)/(Tickets!$G$2:$G$161=$I$3),ROWS($I$4:I6)))&" - "&INDEX(Tickets!$E$2:$E$161,_xlfn.AGGREGATE(15,6,(ROW(Tickets!$G$2:$G$161)-ROW(Tickets!$G$2)+1)/(Tickets!$G$2:$G$161=$I$3),ROWS($I$4:I6))),"") -> WPT-003 - Create frontend React application
A7: =IFERROR(INDEX(Tickets!$A$2:$A$161,_xlfn.AGGREGATE(15,6,(ROW(Tickets!$G$2:$G$161)-ROW(Tickets!$G$2)+1)/(Tickets!$G$2:$G$161=$A$3),ROWS($A$4:A7)))&" - "&INDEX(Tickets!$E$2:$E$161,_xlfn.AGGREGATE(15,6,(ROW(Tickets!$G$2:$G$161)-ROW(Tickets!$G$2)+1)/(Tickets!$G$2:$G$161=$A$3),ROWS($A$4:A7))),"") -> WPT-014 - Create employer registration API | C7: =IFERROR(INDEX(Tickets!$A$2:$A$161,_xlfn.AGGREGATE(15,6,(ROW(Tickets!$G$2:$G$161)-ROW(Tickets!$G$2)+1)/(Tickets!$G$2:$G$161=$C$3),ROWS($C$4:C7)))&" - "&INDEX(Tickets!$E$2:$E$161,_xlfn.AGGREGATE(15,6,(ROW(Tickets!$G$2:$G$161)-ROW(Tickets!$G$2)+1)/(Tickets!$G$2:$G$161=$C$3),ROWS($C$4:C7))),"") | E7: =IFERROR(INDEX(Tickets!$A$2:$A$161,_xlfn.AGGREGATE(15,6,(ROW(Tickets!$G$2:$G$161)-ROW(Tickets!$G$2)+1)/(Tickets!$G$2:$G$161=$E$3),ROWS($E$4:E7)))&" - "&INDEX(Tickets!$E$2:$E$161,_xlfn.AGGREGATE(15,6,(ROW(Tickets!$G$2:$G$161)-ROW(Tickets!$G$2)+1)/(Tickets!$G$2:$G$161=$E$3),ROWS($E$4:E7))),"") -> WPT-009 - Create profile icon menu | G7: =IFERROR(INDEX(Tickets!$A$2:$A$161,_xlfn.AGGREGATE(15,6,(ROW(Tickets!$G$2:$G$161)-ROW(Tickets!$G$2)+1)/(Tickets!$G$2:$G$161=$G$3),ROWS($G$4:G7)))&" - "&INDEX(Tickets!$E$2:$E$161,_xlfn.AGGREGATE(15,6,(ROW(Tickets!$G$2:$G$161)-ROW(Tickets!$G$2)+1)/(Tickets!$G$2:$G$161=$G$3),ROWS($G$4:G7))),"") | I7: =IFERROR(INDEX(Tickets!$A$2:$A$161,_xlfn.AGGREGATE(15,6,(ROW(Tickets!$G$2:$G$161)-ROW(Tickets!$G$2)+1)/(Tickets!$G$2:$G$161=$I$3),ROWS($I$4:I7)))&" - "&INDEX(Tickets!$E$2:$E$161,_xlfn.AGGREGATE(15,6,(ROW(Tickets!$G$2:$G$161)-ROW(Tickets!$G$2)+1)/(Tickets!$G$2:$G$161=$I$3),ROWS($I$4:I7))),"") -> WPT-004 - Create backend API project
A8: =IFERROR(INDEX(Tickets!$A$2:$A$161,_xlfn.AGGREGATE(15,6,(ROW(Tickets!$G$2:$G$161)-ROW(Tickets!$G$2)+1)/(Tickets!$G$2:$G$161=$A$3),ROWS($A$4:A8)))&" - "&INDEX(Tickets!$E$2:$E$161,_xlfn.AGGREGATE(15,6,(ROW(Tickets!$G$2:$G$161)-ROW(Tickets!$G$2)+1)/(Tickets!$G$2:$G$161=$A$3),ROWS($A$4:A8))),"") -> WPT-015 - Validate employer registration fields | C8: =IFERROR(INDEX(Tickets!$A$2:$A$161,_xlfn.AGGREGATE(15,6,(ROW(Tickets!$G$2:$G$161)-ROW(Tickets!$G$2)+1)/(Tickets!$G$2:$G$161=$C$3),ROWS($C$4:C8)))&" - "&INDEX(Tickets!$E$2:$E$161,_xlfn.AGGREGATE(15,6,(ROW(Tickets!$G$2:$G$161)-ROW(Tickets!$G$2)+1)/(Tickets!$G$2:$G$161=$C$3),ROWS($C$4:C8))),"") | E8: =IFERROR(INDEX(Tickets!$A$2:$A$161,_xlfn.AGGREGATE(15,6,(ROW(Tickets!$G$2:$G$161)-ROW(Tickets!$G$2)+1)/(Tickets!$G$2:$G$161=$E$3),ROWS($E$4:E8)))&" - "&INDEX(Tickets!$E$2:$E$161,_xlfn.AGGREGATE(15,6,(ROW(Tickets!$G$2:$G$161)-ROW(Tickets!$G$2)+1)/(Tickets!$G$2:$G$161=$E$3),ROWS($E$4:E8))),"") -> WPT-010 - Create reusable dashboard card component | G8: =IFERROR(INDEX(Tickets!$A$2:$A$161,_xlfn.AGGREGATE(15,6,(ROW(Tickets!$G$2:$G$161)-ROW(Tickets!$G$2)+1)/(Tickets!$G$2:$G$161=$G$3),ROWS($G$4:G8)))&" - "&INDEX(Tickets!$E$2:$E$161,_xlfn.AGGREGATE(15,6,(ROW(Tickets!$G$2:$G$161)-ROW(Tickets!$G$2)+1)/(Tickets!$G$2:$G$161=$G$3),ROWS($G$4:G8))),"") | I8: =IFERROR(INDEX(Tickets!$A$2:$A$161,_xlfn.AGGREGATE(15,6,(ROW(Tickets!$G$2:$G$161)-ROW(Tickets!$G$2)+1)/(Tickets!$G$2:$G$161=$I$3),ROWS($I$4:I8)))&" - "&INDEX(Tickets!$E$2:$E$161,_xlfn.AGGREGATE(15,6,(ROW(Tickets!$G$2:$G$161)-ROW(Tickets!$G$2)+1)/(Tickets!$G$2:$G$161=$I$3),ROWS($I$4:I8))),"") -> WPT-005 - Set up database connection
A9: =IFERROR(INDEX(Tickets!$A$2:$A$161,_xlfn.AGGREGATE(15,6,(ROW(Tickets!$G$2:$G$161)-ROW(Tickets!$G$2)+1)/(Tickets!$G$2:$G$161=$A$3),ROWS($A$4:A9)))&" - "&INDEX(Tickets!$E$2:$E$161,_xlfn.AGGREGATE(15,6,(ROW(Tickets!$G$2:$G$161)-ROW(Tickets!$G$2)+1)/(Tickets!$G$2:$G$161=$A$3),ROWS($A$4:A9))),"") -> WPT-016 - Employee registration | C9: =IFERROR(INDEX(Tickets!$A$2:$A$161,_xlfn.AGGREGATE(15,6,(ROW(Tickets!$G$2:$G$161)-ROW(Tickets!$G$2)+1)/(Tickets!$G$2:$G$161=$C$3),ROWS($C$4:C9)))&" - "&INDEX(Tickets!$E$2:$E$161,_xlfn.AGGREGATE(15,6,(ROW(Tickets!$G$2:$G$161)-ROW(Tickets!$G$2)+1)/(Tickets!$G$2:$G$161=$C$3),ROWS($C$4:C9))),"") | E9: =IFERROR(INDEX(Tickets!$A$2:$A$161,_xlfn.AGGREGATE(15,6,(ROW(Tickets!$G$2:$G$161)-ROW(Tickets!$G$2)+1)/(Tickets!$G$2:$G$161=$E$3),ROWS($E$4:E9)))&" - "&INDEX(Tickets!$E$2:$E$161,_xlfn.AGGREGATE(15,6,(ROW(Tickets!$G$2:$G$161)-ROW(Tickets!$G$2)+1)/(Tickets!$G$2:$G$161=$E$3),ROWS($E$4:E9))),"") | G9: =IFERROR(INDEX(Tickets!$A$2:$A$161,_xlfn.AGGREGATE(15,6,(ROW(Tickets!$G$2:$G$161)-ROW(Tickets!$G$2)+1)/(Tickets!$G$2:$G$161=$G$3),ROWS($G$4:G9)))&" - "&INDEX(Tickets!$E$2:$E$161,_xlfn.AGGREGATE(15,6,(ROW(Tickets!$G$2:$G$161)-ROW(Tickets!$G$2)+1)/(Tickets!$G$2:$G$161=$G$3),ROWS($G$4:G9))),"") | I9: =IFERROR(INDEX(Tickets!$A$2:$A$161,_xlfn.AGGREGATE(15,6,(ROW(Tickets!$G$2:$G$161)-ROW(Tickets!$G$2)+1)/(Tickets!$G$2:$G$161=$I$3),ROWS($I$4:I9)))&" - "&INDEX(Tickets!$E$2:$E$161,_xlfn.AGGREGATE(15,6,(ROW(Tickets!$G$2:$G$161)-ROW(Tickets!$G$2)+1)/(Tickets!$G$2:$G$161=$I$3),ROWS($I$4:I9))),"")
A10: =IFERROR(INDEX(Tickets!$A$2:$A$161,_xlfn.AGGREGATE(15,6,(ROW(Tickets!$G$2:$G$161)-ROW(Tickets!$G$2)+1)/(Tickets!$G$2:$G$161=$A$3),ROWS($A$4:A10)))&" - "&INDEX(Tickets!$E$2:$E$161,_xlfn.AGGREGATE(15,6,(ROW(Tickets!$G$2:$G$161)-ROW(Tickets!$G$2)+1)/(Tickets!$G$2:$G$161=$A$3),ROWS($A$4:A10))),"") -> WPT-017 - Create Employee registration UI | C10: =IFERROR(INDEX(Tickets!$A$2:$A$161,_xlfn.AGGREGATE(15,6,(ROW(Tickets!$G$2:$G$161)-ROW(Tickets!$G$2)+1)/(Tickets!$G$2:$G$161=$C$3),ROWS($C$4:C10)))&" - "&INDEX(Tickets!$E$2:$E$161,_xlfn.AGGREGATE(15,6,(ROW(Tickets!$G$2:$G$161)-ROW(Tickets!$G$2)+1)/(Tickets!$G$2:$G$161=$C$3),ROWS($C$4:C10))),"") | E10: =IFERROR(INDEX(Tickets!$A$2:$A$161,_xlfn.AGGREGATE(15,6,(ROW(Tickets!$G$2:$G$161)-ROW(Tickets!$G$2)+1)/(Tickets!$G$2:$G$161=$E$3),ROWS($E$4:E10)))&" - "&INDEX(Tickets!$E$2:$E$161,_xlfn.AGGREGATE(15,6,(ROW(Tickets!$G$2:$G$161)-ROW(Tickets!$G$2)+1)/(Tickets!$G$2:$G$161=$E$3),ROWS($E$4:E10))),"") | G10: =IFERROR(INDEX(Tickets!$A$2:$A$161,_xlfn.AGGREGATE(15,6,(ROW(Tickets!$G$2:$G$161)-ROW(Tickets!$G$2)+1)/(Tickets!$G$2:$G$161=$G$3),ROWS($G$4:G10)))&" - "&INDEX(Tickets!$E$2:$E$161,_xlfn.AGGREGATE(15,6,(ROW(Tickets!$G$2:$G$161)-ROW(Tickets!$G$2)+1)/(Tickets!$G$2:$G$161=$G$3),ROWS($G$4:G10))),"") | I10: =IFERROR(INDEX(Tickets!$A$2:$A$161,_xlfn.AGGREGATE(15,6,(ROW(Tickets!$G$2:$G$161)-ROW(Tickets!$G$2)+1)/(Tickets!$G$2:$G$161=$I$3),ROWS($I$4:I10)))&" - "&INDEX(Tickets!$E$2:$E$161,_xlfn.AGGREGATE(15,6,(ROW(Tickets!$G$2:$G$161)-ROW(Tickets!$G$2)+1)/(Tickets!$G$2:$G$161=$I$3),ROWS($I$4:I10))),"")
A11: =IFERROR(INDEX(Tickets!$A$2:$A$161,_xlfn.AGGREGATE(15,6,(ROW(Tickets!$G$2:$G$161)-ROW(Tickets!$G$2)+1)/(Tickets!$G$2:$G$161=$A$3),ROWS($A$4:A11)))&" - "&INDEX(Tickets!$E$2:$E$161,_xlfn.AGGREGATE(15,6,(ROW(Tickets!$G$2:$G$161)-ROW(Tickets!$G$2)+1)/(Tickets!$G$2:$G$161=$A$3),ROWS($A$4:A11))),"") -> WPT-018 - Create Employee registration API | C11: =IFERROR(INDEX(Tickets!$A$2:$A$161,_xlfn.AGGREGATE(15,6,(ROW(Tickets!$G$2:$G$161)-ROW(Tickets!$G$2)+1)/(Tickets!$G$2:$G$161=$C$3),ROWS($C$4:C11)))&" - "&INDEX(Tickets!$E$2:$E$161,_xlfn.AGGREGATE(15,6,(ROW(Tickets!$G$2:$G$161)-ROW(Tickets!$G$2)+1)/(Tickets!$G$2:$G$161=$C$3),ROWS($C$4:C11))),"") | E11: =IFERROR(INDEX(Tickets!$A$2:$A$161,_xlfn.AGGREGATE(15,6,(ROW(Tickets!$G$2:$G$161)-ROW(Tickets!$G$2)+1)/(Tickets!$G$2:$G$161=$E$3),ROWS($E$4:E11)))&" - "&INDEX(Tickets!$E$2:$E$161,_xlfn.AGGREGATE(15,6,(ROW(Tickets!$G$2:$G$161)-ROW(Tickets!$G$2)+1)/(Tickets!$G$2:$G$161=$E$3),ROWS($E$4:E11))),"") | G11: =IFERROR(INDEX(Tickets!$A$2:$A$161,_xlfn.AGGREGATE(15,6,(ROW(Tickets!$G$2:$G$161)-ROW(Tickets!$G$2)+1)/(Tickets!$G$2:$G$161=$G$3),ROWS($G$4:G11)))&" - "&INDEX(Tickets!$E$2:$E$161,_xlfn.AGGREGATE(15,6,(ROW(Tickets!$G$2:$G$161)-ROW(Tickets!$G$2)+1)/(Tickets!$G$2:$G$161=$G$3),ROWS($G$4:G11))),"") | I11: =IFERROR(INDEX(Tickets!$A$2:$A$161,_xlfn.AGGREGATE(15,6,(ROW(Tickets!$G$2:$G$161)-ROW(Tickets!$G$2)+1)/(Tickets!$G$2:$G$161=$I$3),ROWS($I$4:I11)))&" - "&INDEX(Tickets!$E$2:$E$161,_xlfn.AGGREGATE(15,6,(ROW(Tickets!$G$2:$G$161)-ROW(Tickets!$G$2)+1)/(Tickets!$G$2:$G$161=$I$3),ROWS($I$4:I11))),"")
A12: =IFERROR(INDEX(Tickets!$A$2:$A$161,_xlfn.AGGREGATE(15,6,(ROW(Tickets!$G$2:$G$161)-ROW(Tickets!$G$2)+1)/(Tickets!$G$2:$G$161=$A$3),ROWS($A$4:A12)))&" - "&INDEX(Tickets!$E$2:$E$161,_xlfn.AGGREGATE(15,6,(ROW(Tickets!$G$2:$G$161)-ROW(Tickets!$G$2)+1)/(Tickets!$G$2:$G$161=$A$3),ROWS($A$4:A12))),"") -> WPT-019 - Validate Employee registration fields | C12: =IFERROR(INDEX(Tickets!$A$2:$A$161,_xlfn.AGGREGATE(15,6,(ROW(Tickets!$G$2:$G$161)-ROW(Tickets!$G$2)+1)/(Tickets!$G$2:$G$161=$C$3),ROWS($C$4:C12)))&" - "&INDEX(Tickets!$E$2:$E$161,_xlfn.AGGREGATE(15,6,(ROW(Tickets!$G$2:$G$161)-ROW(Tickets!$G$2)+1)/(Tickets!$G$2:$G$161=$C$3),ROWS($C$4:C12))),"") | E12: =IFERROR(INDEX(Tickets!$A$2:$A$161,_xlfn.AGGREGATE(15,6,(ROW(Tickets!$G$2:$G$161)-ROW(Tickets!$G$2)+1)/(Tickets!$G$2:$G$161=$E$3),ROWS($E$4:E12)))&" - "&INDEX(Tickets!$E$2:$E$161,_xlfn.AGGREGATE(15,6,(ROW(Tickets!$G$2:$G$161)-ROW(Tickets!$G$2)+1)/(Tickets!$G$2:$G$161=$E$3),ROWS($E$4:E12))),"") | G12: =IFERROR(INDEX(Tickets!$A$2:$A$161,_xlfn.AGGREGATE(15,6,(ROW(Tickets!$G$2:$G$161)-ROW(Tickets!$G$2)+1)/(Tickets!$G$2:$G$161=$G$3),ROWS($G$4:G12)))&" - "&INDEX(Tickets!$E$2:$E$161,_xlfn.AGGREGATE(15,6,(ROW(Tickets!$G$2:$G$161)-ROW(Tickets!$G$2)+1)/(Tickets!$G$2:$G$161=$G$3),ROWS($G$4:G12))),"") | I12: =IFERROR(INDEX(Tickets!$A$2:$A$161,_xlfn.AGGREGATE(15,6,(ROW(Tickets!$G$2:$G$161)-ROW(Tickets!$G$2)+1)/(Tickets!$G$2:$G$161=$I$3),ROWS($I$4:I12)))&" - "&INDEX(Tickets!$E$2:$E$161,_xlfn.AGGREGATE(15,6,(ROW(Tickets!$G$2:$G$161)-ROW(Tickets!$G$2)+1)/(Tickets!$G$2:$G$161=$I$3),ROWS($I$4:I12))),"")
A13: =IFERROR(INDEX(Tickets!$A$2:$A$161,_xlfn.AGGREGATE(15,6,(ROW(Tickets!$G$2:$G$161)-ROW(Tickets!$G$2)+1)/(Tickets!$G$2:$G$161=$A$3),ROWS($A$4:A13)))&" - "&INDEX(Tickets!$E$2:$E$161,_xlfn.AGGREGATE(15,6,(ROW(Tickets!$G$2:$G$161)-ROW(Tickets!$G$2)+1)/(Tickets!$G$2:$G$161=$A$3),ROWS($A$4:A13))),"") -> WPT-020 - Login for employer and Employee | C13: =IFERROR(INDEX(Tickets!$A$2:$A$161,_xlfn.AGGREGATE(15,6,(ROW(Tickets!$G$2:$G$161)-ROW(Tickets!$G$2)+1)/(Tickets!$G$2:$G$161=$C$3),ROWS($C$4:C13)))&" - "&INDEX(Tickets!$E$2:$E$161,_xlfn.AGGREGATE(15,6,(ROW(Tickets!$G$2:$G$161)-ROW(Tickets!$G$2)+1)/(Tickets!$G$2:$G$161=$C$3),ROWS($C$4:C13))),"") | E13: =IFERROR(INDEX(Tickets!$A$2:$A$161,_xlfn.AGGREGATE(15,6,(ROW(Tickets!$G$2:$G$161)-ROW(Tickets!$G$2)+1)/(Tickets!$G$2:$G$161=$E$3),ROWS($E$4:E13)))&" - "&INDEX(Tickets!$E$2:$E$161,_xlfn.AGGREGATE(15,6,(ROW(Tickets!$G$2:$G$161)-ROW(Tickets!$G$2)+1)/(Tickets!$G$2:$G$161=$E$3),ROWS($E$4:E13))),"") | G13: =IFERROR(INDEX(Tickets!$A$2:$A$161,_xlfn.AGGREGATE(15,6,(ROW(Tickets!$G$2:$G$161)-ROW(Tickets!$G$2)+1)/(Tickets!$G$2:$G$161=$G$3),ROWS($G$4:G13)))&" - "&INDEX(Tickets!$E$2:$E$161,_xlfn.AGGREGATE(15,6,(ROW(Tickets!$G$2:$G$161)-ROW(Tickets!$G$2)+1)/(Tickets!$G$2:$G$161=$G$3),ROWS($G$4:G13))),"") | I13: =IFERROR(INDEX(Tickets!$A$2:$A$161,_xlfn.AGGREGATE(15,6,(ROW(Tickets!$G$2:$G$161)-ROW(Tickets!$G$2)+1)/(Tickets!$G$2:$G$161=$I$3),ROWS($I$4:I13)))&" - "&INDEX(Tickets!$E$2:$E$161,_xlfn.AGGREGATE(15,6,(ROW(Tickets!$G$2:$G$161)-ROW(Tickets!$G$2)+1)/(Tickets!$G$2:$G$161=$I$3),ROWS($I$4:I13))),"")
A14: =IFERROR(INDEX(Tickets!$A$2:$A$161,_xlfn.AGGREGATE(15,6,(ROW(Tickets!$G$2:$G$161)-ROW(Tickets!$G$2)+1)/(Tickets!$G$2:$G$161=$A$3),ROWS($A$4:A14)))&" - "&INDEX(Tickets!$E$2:$E$161,_xlfn.AGGREGATE(15,6,(ROW(Tickets!$G$2:$G$161)-ROW(Tickets!$G$2)+1)/(Tickets!$G$2:$G$161=$A$3),ROWS($A$4:A14))),"") -> WPT-021 - Create login UI | C14: =IFERROR(INDEX(Tickets!$A$2:$A$161,_xlfn.AGGREGATE(15,6,(ROW(Tickets!$G$2:$G$161)-ROW(Tickets!$G$2)+1)/(Tickets!$G$2:$G$161=$C$3),ROWS($C$4:C14)))&" - "&INDEX(Tickets!$E$2:$E$161,_xlfn.AGGREGATE(15,6,(ROW(Tickets!$G$2:$G$161)-ROW(Tickets!$G$2)+1)/(Tickets!$G$2:$G$161=$C$3),ROWS($C$4:C14))),"") | E14: =IFERROR(INDEX(Tickets!$A$2:$A$161,_xlfn.AGGREGATE(15,6,(ROW(Tickets!$G$2:$G$161)-ROW(Tickets!$G$2)+1)/(Tickets!$G$2:$G$161=$E$3),ROWS($E$4:E14)))&" - "&INDEX(Tickets!$E$2:$E$161,_xlfn.AGGREGATE(15,6,(ROW(Tickets!$G$2:$G$161)-ROW(Tickets!$G$2)+1)/(Tickets!$G$2:$G$161=$E$3),ROWS($E$4:E14))),"") | G14: =IFERROR(INDEX(Tickets!$A$2:$A$161,_xlfn.AGGREGATE(15,6,(ROW(Tickets!$G$2:$G$161)-ROW(Tickets!$G$2)+1)/(Tickets!$G$2:$G$161=$G$3),ROWS($G$4:G14)))&" - "&INDEX(Tickets!$E$2:$E$161,_xlfn.AGGREGATE(15,6,(ROW(Tickets!$G$2:$G$161)-ROW(Tickets!$G$2)+1)/(Tickets!$G$2:$G$161=$G$3),ROWS($G$4:G14))),"") | I14: =IFERROR(INDEX(Tickets!$A$2:$A$161,_xlfn.AGGREGATE(15,6,(ROW(Tickets!$G$2:$G$161)-ROW(Tickets!$G$2)+1)/(Tickets!$G$2:$G$161=$I$3),ROWS($I$4:I14)))&" - "&INDEX(Tickets!$E$2:$E$161,_xlfn.AGGREGATE(15,6,(ROW(Tickets!$G$2:$G$161)-ROW(Tickets!$G$2)+1)/(Tickets!$G$2:$G$161=$I$3),ROWS($I$4:I14))),"")
A15: =IFERROR(INDEX(Tickets!$A$2:$A$161,_xlfn.AGGREGATE(15,6,(ROW(Tickets!$G$2:$G$161)-ROW(Tickets!$G$2)+1)/(Tickets!$G$2:$G$161=$A$3),ROWS($A$4:A15)))&" - "&INDEX(Tickets!$E$2:$E$161,_xlfn.AGGREGATE(15,6,(ROW(Tickets!$G$2:$G$161)-ROW(Tickets!$G$2)+1)/(Tickets!$G$2:$G$161=$A$3),ROWS($A$4:A15))),"") -> WPT-022 - Create login API | C15: =IFERROR(INDEX(Tickets!$A$2:$A$161,_xlfn.AGGREGATE(15,6,(ROW(Tickets!$G$2:$G$161)-ROW(Tickets!$G$2)+1)/(Tickets!$G$2:$G$161=$C$3),ROWS($C$4:C15)))&" - "&INDEX(Tickets!$E$2:$E$161,_xlfn.AGGREGATE(15,6,(ROW(Tickets!$G$2:$G$161)-ROW(Tickets!$G$2)+1)/(Tickets!$G$2:$G$161=$C$3),ROWS($C$4:C15))),"") | E15: =IFERROR(INDEX(Tickets!$A$2:$A$161,_xlfn.AGGREGATE(15,6,(ROW(Tickets!$G$2:$G$161)-ROW(Tickets!$G$2)+1)/(Tickets!$G$2:$G$161=$E$3),ROWS($E$4:E15)))&" - "&INDEX(Tickets!$E$2:$E$161,_xlfn.AGGREGATE(15,6,(ROW(Tickets!$G$2:$G$161)-ROW(Tickets!$G$2)+1)/(Tickets!$G$2:$G$161=$E$3),ROWS($E$4:E15))),"") | G15: =IFERROR(INDEX(Tickets!$A$2:$A$161,_xlfn.AGGREGATE(15,6,(ROW(Tickets!$G$2:$G$161)-ROW(Tickets!$G$2)+1)/(Tickets!$G$2:$G$161=$G$3),ROWS($G$4:G15)))&" - "&INDEX(Tickets!$E$2:$E$161,_xlfn.AGGREGATE(15,6,(ROW(Tickets!$G$2:$G$161)-ROW(Tickets!$G$2)+1)/(Tickets!$G$2:$G$161=$G$3),ROWS($G$4:G15))),"") | I15: =IFERROR(INDEX(Tickets!$A$2:$A$161,_xlfn.AGGREGATE(15,6,(ROW(Tickets!$G$2:$G$161)-ROW(Tickets!$G$2)+1)/(Tickets!$G$2:$G$161=$I$3),ROWS($I$4:I15)))&" - "&INDEX(Tickets!$E$2:$E$161,_xlfn.AGGREGATE(15,6,(ROW(Tickets!$G$2:$G$161)-ROW(Tickets!$G$2)+1)/(Tickets!$G$2:$G$161=$I$3),ROWS($I$4:I15))),"")
... A168: =IFERROR(INDEX(Tickets!$A$2:$A$161,_xlfn.AGGREGATE(15,6,(ROW(Tickets!$G$2:$G$161)-ROW(Tickets!$G$2)+1)/(Tickets!$G$2:$G$161=$A$3),ROWS($A$4:A168)))&" - "&INDEX(Tickets!$E$2:$E$161,_xlfn.AGGREGATE(15,6,(ROW(Tickets!$G$2:$G$161)-ROW(Tickets!$G$2)+1)/(Tickets!$G$2:$G$161=$A$3),ROWS($A$4:A168))),"") | C168: =IFERROR(INDEX(Tickets!$A$2:$A$161,_xlfn.AGGREGATE(15,6,(ROW(Tickets!$G$2:$G$161)-ROW(Tickets!$G$2)+1)/(Tickets!$G$2:$G$161=$C$3),ROWS($C$4:C168)))&" - "&INDEX(Tickets!$E$2:$E$161,_xlfn.AGGREGATE(15,6,(ROW(Tickets!$G$2:$G$161)-ROW(Tickets!$G$2)+1)/(Tickets!$G$2:$G$161=$C$3),ROWS($C$4:C168))),"") | E168: =IFERROR(INDEX(Tickets!$A$2:$A$161,_xlfn.AGGREGATE(15,6,(ROW(Tickets!$G$2:$G$161)-ROW(Tickets!$G$2)+1)/(Tickets!$G$2:$G$161=$E$3),ROWS($E$4:E168)))&" - "&INDEX(Tickets!$E$2:$E$161,_xlfn.AGGREGATE(15,6,(ROW(Tickets!$G$2:$G$161)-ROW(Tickets!$G$2)+1)/(Tickets!$G$2:$G$161=$E$3),ROWS($E$4:E168))),"") | G168: =IFERROR(INDEX(Tickets!$A$2:$A$161,_xlfn.AGGREGATE(15,6,(ROW(Tickets!$G$2:$G$161)-ROW(Tickets!$G$2)+1)/(Tickets!$G$2:$G$161=$G$3),ROWS($G$4:G168)))&" - "&INDEX(Tickets!$E$2:$E$161,_xlfn.AGGREGATE(15,6,(ROW(Tickets!$G$2:$G$161)-ROW(Tickets!$G$2)+1)/(Tickets!$G$2:$G$161=$G$3),ROWS($G$4:G168))),"") | I168: =IFERROR(INDEX(Tickets!$A$2:$A$161,_xlfn.AGGREGATE(15,6,(ROW(Tickets!$G$2:$G$161)-ROW(Tickets!$G$2)+1)/(Tickets!$G$2:$G$161=$I$3),ROWS($I$4:I168)))&" - "&INDEX(Tickets!$E$2:$E$161,_xlfn.AGGREGATE(15,6,(ROW(Tickets!$G$2:$G$161)-ROW(Tickets!$G$2)+1)/(Tickets!$G$2:$G$161=$I$3),ROWS($I$4:I168))),"")

Sheet Workload Dashboard
A1: WayPoint Workload Dashboard
A3: Team Member | B3: Open Tickets | C3: Assigned Tickets | D3: Assigned SP | E3: Completed SP | F3: Remaining SP | G3: Completion % | H3: In Progress | I3: Testing
A4: {=IFERROR(INDEX(tblTeam[Name],_xlfn.AGGREGATE(15,6,(ROW(tblTeam[Name])-MIN(ROW(tblTeam[Name]))+1)/(tblTeam[Active]="Yes"),ROWS($A$4:A4))),"")} -> Pragna | B4: =COUNTIFS(tblTickets[Assignee],A4,tblTickets[Status],"<>Done") -> 13 | C4: =COUNTIF(tblTickets[Assignee],A4) -> 18 | D4: =SUMIF(tblTickets[Assignee],A4,tblTickets[Story Points]) -> 71 | E4: =SUMIFS(tblTickets[Story Points],tblTickets[Assignee],A4,tblTickets[Status],"Done") -> 18 | F4: =D4-E4 -> 53 | G4: =IFERROR(E4/D4,0) -> 0.25352113 | H4: =COUNTIFS(tblTickets[Assignee],A4,tblTickets[Status],"In Progress") -> 5 | I4: =COUNTIFS(tblTickets[Assignee],A4,tblTickets[Status],"Testing") -> 0
A5: {=IFERROR(INDEX(tblTeam[Name],_xlfn.AGGREGATE(15,6,(ROW(tblTeam[Name])-MIN(ROW(tblTeam[Name]))+1)/(tblTeam[Active]="Yes"),ROWS($A$4:A5))),"")} -> Vasavi | B5: =COUNTIFS(tblTickets[Assignee],A5,tblTickets[Status],"<>Done") -> 0 | C5: =COUNTIF(tblTickets[Assignee],A5) -> 0 | D5: =SUMIF(tblTickets[Assignee],A5,tblTickets[Story Points]) -> 0 | E5: =SUMIFS(tblTickets[Story Points],tblTickets[Assignee],A5,tblTickets[Status],"Done") -> 0 | F5: =D5-E5 -> 0 | G5: =IFERROR(E5/D5,0) -> 0 | H5: =COUNTIFS(tblTickets[Assignee],A5,tblTickets[Status],"In Progress") -> 0 | I5: =COUNTIFS(tblTickets[Assignee],A5,tblTickets[Status],"Testing") -> 0
A6: {=IFERROR(INDEX(tblTeam[Name],_xlfn.AGGREGATE(15,6,(ROW(tblTeam[Name])-MIN(ROW(tblTeam[Name]))+1)/(tblTeam[Active]="Yes"),ROWS($A$4:A6))),"")} -> Niharika | B6: =COUNTIFS(tblTickets[Assignee],A6,tblTickets[Status],"<>Done") -> 0 | C6: =COUNTIF(tblTickets[Assignee],A6) -> 0 | D6: =SUMIF(tblTickets[Assignee],A6,tblTickets[Story Points]) -> 0 | E6: =SUMIFS(tblTickets[Story Points],tblTickets[Assignee],A6,tblTickets[Status],"Done") -> 0 | F6: =D6-E6 -> 0 | G6: =IFERROR(E6/D6,0) -> 0 | H6: =COUNTIFS(tblTickets[Assignee],A6,tblTickets[Status],"In Progress") -> 0 | I6: =COUNTIFS(tblTickets[Assignee],A6,tblTickets[Status],"Testing") -> 0
A7: {=IFERROR(INDEX(tblTeam[Name],_xlfn.AGGREGATE(15,6,(ROW(tblTeam[Name])-MIN(ROW(tblTeam[Name]))+1)/(tblTeam[Active]="Yes"),ROWS($A$4:A7))),"")} -> Arun | B7: =COUNTIFS(tblTickets[Assignee],A7,tblTickets[Status],"<>Done") -> 0 | C7: =COUNTIF(tblTickets[Assignee],A7) -> 0 | D7: =SUMIF(tblTickets[Assignee],A7,tblTickets[Story Points]) -> 0 | E7: =SUMIFS(tblTickets[Story Points],tblTickets[Assignee],A7,tblTickets[Status],"Done") -> 0 | F7: =D7-E7 -> 0 | G7: =IFERROR(E7/D7,0) -> 0 | H7: =COUNTIFS(tblTickets[Assignee],A7,tblTickets[Status],"In Progress") -> 0 | I7: =COUNTIFS(tblTickets[Assignee],A7,tblTickets[Status],"Testing") -> 0
A8: {=IFERROR(INDEX(tblTeam[Name],_xlfn.AGGREGATE(15,6,(ROW(tblTeam[Name])-MIN(ROW(tblTeam[Name]))+1)/(tblTeam[Active]="Yes"),ROWS($A$4:A8))),"")} -> Giridhar | B8: =COUNTIFS(tblTickets[Assignee],A8,tblTickets[Status],"<>Done") -> 1 | C8: =COUNTIF(tblTickets[Assignee],A8) -> 1 | D8: =SUMIF(tblTickets[Assignee],A8,tblTickets[Story Points]) -> 5 | E8: =SUMIFS(tblTickets[Story Points],tblTickets[Assignee],A8,tblTickets[Status],"Done") -> 0 | F8: =D8-E8 -> 5 | G8: =IFERROR(E8/D8,0) -> 0 | H8: =COUNTIFS(tblTickets[Assignee],A8,tblTickets[Status],"In Progress") -> 0 | I8: =COUNTIFS(tblTickets[Assignee],A8,tblTickets[Status],"Testing") -> 0
A9: {=IFERROR(INDEX(tblTeam[Name],_xlfn.AGGREGATE(15,6,(ROW(tblTeam[Name])-MIN(ROW(tblTeam[Name]))+1)/(tblTeam[Active]="Yes"),ROWS($A$4:A9))),"")} -> Mahesh | B9: =COUNTIFS(tblTickets[Assignee],A9,tblTickets[Status],"<>Done") -> 0 | C9: =COUNTIF(tblTickets[Assignee],A9) -> 0 | D9: =SUMIF(tblTickets[Assignee],A9,tblTickets[Story Points]) -> 0 | E9: =SUMIFS(tblTickets[Story Points],tblTickets[Assignee],A9,tblTickets[Status],"Done") -> 0 | F9: =D9-E9 -> 0 | G9: =IFERROR(E9/D9,0) -> 0 | H9: =COUNTIFS(tblTickets[Assignee],A9,tblTickets[Status],"In Progress") -> 0 | I9: =COUNTIFS(tblTickets[Assignee],A9,tblTickets[Status],"Testing") -> 0
A10: {=IFERROR(INDEX(tblTeam[Name],_xlfn.AGGREGATE(15,6,(ROW(tblTeam[Name])-MIN(ROW(tblTeam[Name]))+1)/(tblTeam[Active]="Yes"),ROWS($A$4:A10))),"")} -> Jhansi | B10: =COUNTIFS(tblTickets[Assignee],A10,tblTickets[Status],"<>Done") -> 5 | C10: =COUNTIF(tblTickets[Assignee],A10) -> 5 | D10: =SUMIF(tblTickets[Assignee],A10,tblTickets[Story Points]) -> 26 | E10: =SUMIFS(tblTickets[Story Points],tblTickets[Assignee],A10,tblTickets[Status],"Done") -> 0 | F10: =D10-E10 -> 26 | G10: =IFERROR(E10/D10,0) -> 0 | H10: =COUNTIFS(tblTickets[Assignee],A10,tblTickets[Status],"In Progress") -> 0 | I10: =COUNTIFS(tblTickets[Assignee],A10,tblTickets[Status],"Testing") -> 0
A11: {=IFERROR(INDEX(tblTeam[Name],_xlfn.AGGREGATE(15,6,(ROW(tblTeam[Name])-MIN(ROW(tblTeam[Name]))+1)/(tblTeam[Active]="Yes"),ROWS($A$4:A11))),"")} -> Geethanjali | B11: =COUNTIFS(tblTickets[Assignee],A11,tblTickets[Status],"<>Done") -> 0 | C11: =COUNTIF(tblTickets[Assignee],A11) -> 0 | D11: =SUMIF(tblTickets[Assignee],A11,tblTickets[Story Points]) -> 0 | E11: =SUMIFS(tblTickets[Story Points],tblTickets[Assignee],A11,tblTickets[Status],"Done") -> 0 | F11: =D11-E11 -> 0 | G11: =IFERROR(E11/D11,0) -> 0 | H11: =COUNTIFS(tblTickets[Assignee],A11,tblTickets[Status],"In Progress") -> 0 | I11: =COUNTIFS(tblTickets[Assignee],A11,tblTickets[Status],"Testing") -> 0
A12: {=IFERROR(INDEX(tblTeam[Name],_xlfn.AGGREGATE(15,6,(ROW(tblTeam[Name])-MIN(ROW(tblTeam[Name]))+1)/(tblTeam[Active]="Yes"),ROWS($A$4:A12))),"")} -> Mani | B12: =COUNTIFS(tblTickets[Assignee],A12,tblTickets[Status],"<>Done") -> 0 | C12: =COUNTIF(tblTickets[Assignee],A12) -> 0 | D12: =SUMIF(tblTickets[Assignee],A12,tblTickets[Story Points]) -> 0 | E12: =SUMIFS(tblTickets[Story Points],tblTickets[Assignee],A12,tblTickets[Status],"Done") -> 0 | F12: =D12-E12 -> 0 | G12: =IFERROR(E12/D12,0) -> 0 | H12: =COUNTIFS(tblTickets[Assignee],A12,tblTickets[Status],"In Progress") -> 0 | I12: =COUNTIFS(tblTickets[Assignee],A12,tblTickets[Status],"Testing") -> 0

Sheet Reports & Charts
A1: WayPoint Reports & Charts
A3: Status | B3: Ticket Count | D3: Type | E3: Ticket Count | G3: Module | H3: Ticket Count
A4: Backlog | B4: =COUNTIF(tblTickets[Status],A4) -> 150 | D4: Epic | E4: =COUNTIF(tblTickets[Type],D4) -> 13 | G4: Authentication | H4: =COUNTIF(tblTickets[Module],G4) -> 16
A5: Ready | B5: =COUNTIF(tblTickets[Status],A5) -> 0 | D5: Story | E5: =COUNTIF(tblTickets[Type],D5) -> 34 | G5: Candidate Dashboard | H5: =COUNTIF(tblTickets[Module],G5) -> 0
A6: In Progress | B6: =COUNTIF(tblTickets[Status],A6) -> 5 | D6: Task | E6: =COUNTIF(tblTickets[Type],D6) -> 112 | G6: Candidate Event Management | H6: =COUNTIF(tblTickets[Module],G6) -> 0
A7: Testing | B7: =COUNTIF(tblTickets[Status],A7) -> 0 | D7: Subtask | E7: =COUNTIF(tblTickets[Type],D7) -> 1 | G7: Candidate Job Management | H7: =COUNTIF(tblTickets[Module],G7) -> 0
A8: Done | B8: =COUNTIF(tblTickets[Status],A8) -> 5 | G8: Candidate Portal | H8: =COUNTIF(tblTickets[Module],G8) -> 0
G9: Candidate Profile | H9: =COUNTIF(tblTickets[Module],G9) -> 0
G10: Contact Support | H10: =COUNTIF(tblTickets[Module],G10) -> 6
G11: Data Model | H11: =COUNTIF(tblTickets[Module],G11) -> 12
G12: Data Model and API | H12: =COUNTIF(tblTickets[Module],G12) -> 1
G13: Employer Application Tracking | H13: =COUNTIF(tblTickets[Module],G13) -> 5
G14: Employer Dashboard | H14: =COUNTIF(tblTickets[Module],G14) -> 6
G15: Employer Event Management | H15: =COUNTIF(tblTickets[Module],G15) -> 18
G16: Employer Job Management | H16: =COUNTIF(tblTickets[Module],G16) -> 20
G17: Employer Portal | H17: =COUNTIF(tblTickets[Module],G17) -> 1
G18: Employer Profile | H18: =COUNTIF(tblTickets[Module],G18) -> 4
G19: Notifications | H19: =COUNTIF(tblTickets[Module],G19) -> 5
G20: Project Foundation | H20: =COUNTIF(tblTickets[Module],G20) -> 7
... G23: Shared UI | H23: =COUNTIF(tblTickets[Module],G23) -> 3

Sheet Lookup Values
A1: Ticket Types | C1: Statuses | E1: Story Points | G1: Modules
A2: Epic | C2: Backlog | E2: 0 | G2: Authentication
A3: Story | C3: Ready | E3: 1 | G3: Employee Dashboard
A4: Task | C4: In Progress | E4: 2 | G4: Employee Event Management
A5: Subtask | C5: Testing | E5: 3 | G5: Employee Job Management
A6: Bug | C6: Done | E6: 5 | G6: Employee Portal
C7: In Review | E7: 8 | G7: Employee Profile
E8: 13 | G8: Contact Support
E9: 21 | G9: Data Model
G10: Data Model and API
G11: Employer Application Management
G12: Employer Dashboard
G13: Employer Event Management
G14: Employer Job Management
G15: Employer Portal
G16: Employer Profile
G17: Notifications
G18: Project Foundation
G19: Quality Assurance
G20: Shared UI

Sheet Instructions
A1: How to Use This Workbook
A3: 1. Use the Tickets sheet as the main working backlog. | B3: The entire team can update Assignee, Status, Story Points, and Dates there.
A4: 2. Add new tickets below the existing table. | B4: Use the next WPT number and keep the Parent ID to preserve Epic > Story > Task > Subtask relationships.
A5: 3. Use dropdowns to keep data consistent. | B5: Type, Module, Assignee, Status, and Story Points have built-in dropdowns.
A6: 4. Dashboards update automatically. | B6: Home Dashboard, Workload Dashboard, Kanban Board, and Reports & Charts are formula-driven.
A7: 5. Completed work rule. | B7: Story points count as completed only when Status equals Done.
A8: 6. Roles can be updated later. | B8: Update the Team Members sheet when roles and skills are finalized.
A9: 7. No protection or macros. | B9: This workbook has no sheet protection, passwords, locked cells, hidden sheets, or macros — every cell is editable.
